Workbook

Sheet Dashboard 
A1: Prepared by : Tayybah Imran
A2: Date: 01-04-2026
A3: Disclaimer: “Educational reconstruction based on publicly available UBL Annual Report 2024. Not official financial advice.”
A4: UBL Financial Statements 2024 vs 2023 – Summary Dashboard
A5: 2024 vs 2023 | All figures in PKR '000
A7: Key Highlights
A8: Metrics | B8: 2024 | C8: 2023 | D8: Growth %
A9: Total Assets | B9: ='Statement of Financial Position'!C14 -> 8069097277 | C9: ='Statement of Financial Position'!D14 -> 5904674886 | D9: =(B9-C9)/C9 -> 0.36656081
A10: Net Advances | B10: ='Statement of Financial Position'!C8 -> 1443481944 | C10: ='Statement of Financial Position'!D8 -> 872040932 | D10: =(B10-C10)/C10 -> 0.6552915
A11: Total Deposits | B11: ='Statement of Financial Position'!C18 -> 2639875985 | C11: ='Statement of Financial Position'!D18 -> 2634716102 | D11: =(B11-C11)/C11 -> 0.0019584209
A12: Profit After Taxation | B12: ='Profit and Loss Statement'!C35 -> 75777444 | C12: ='Profit and Loss Statement'!D35 -> 56470921 | D12: =(B12-C12)/C12 -> 0.34188433
A13: Net Mark-up / Interest Income | B13: ='Profit and Loss Statement'!C5 -> 173547881 | C13: ='Profit and Loss Statement'!D5 -> 148975069 | D13: =(B13-C13)/C13 -> 0.1649458
A15: Key Performance Ratios
B16: 2024 value | C16: 2023 value
A17: Return on Assets (ROA) | B17: ='Profit and Loss Statement'!C35/AVERAGE('Statement of Financial Position'!C14,'Statement of Financial Position'!D14) -> 0.010845668 | C17: ='Profit and Loss Statement'!D35/AVERAGE('Statement of Financial Position'!D14,'Statement of Financial Position'!E14) -> 0.0095637647
A18: Return on Equity (ROE) | B18: ='Profit and Loss Statement'!C41/AVERAGE('Statement of Financial Position'!C31+'Statement of Financial Position'!D31)/2 -> 0.063505586 | C18: ='Profit and Loss Statement'!D41/AVERAGE('Statement of Financial Position'!D31+'Statement of Financial Position'!E31)/2 -> 0.10175562
A19: Net Interest Margin (NIM) | B19: ='Profit and Loss Statement'!C5/AVERAGE('Statement of Financial Position'!C14,'Statement of Financial Position'!D14) -> 0.024839088 | C19: ='Profit and Loss Statement'!D5/AVERAGE('Statement of Financial Position'!D14,'Statement of Financial Position'!E14) -> 0.025230021
A20: Cost to Income Ratio | B20: ='Profit and Loss Statement'!C22/('Profit and Loss Statement'!C16) -> 0.39000288 | C20: ='Profit and Loss Statement'!D22/('Profit and Loss Statement'!D16) -> 0.39175344
A21: Advances to Deposits Ratio (ADR) | B21: ='Statement of Financial Position'!C8/'Statement of Financial Position'!C18 -> 0.54679915 | C21: ='Statement of Financial Position'!D8/'Statement of Financial Position'!D18 -> 0.33098099
A22: Earnings Per Share (EPS) | B22: ='Profit and Loss Statement'!C50 -> 61.392828 | C22: ='Profit and Loss Statement'!D50 -> 45.046553
A23: *Note:-
A24: Ratios calculated on average assets/equity for accuracy.”
A26: Charts
A27: Asset Composition 2024
A28: ASSETS | B28: 2024
A29: Cash and balances with treasury banks | B29: 310836376
A30: Balances with other banks | B30: 59968246
A31: Lendings to financial institutions | B31: 18492483
A32: Investments | B32: 5889765841
A33: Advances | B33: 1443481944
A34: Property and Equipment | B34: 85591999
A35: Right-of-use of assets | B35: 10231121
A36: Intangible assets | B36: 2792016
A37: Deferred tax assets
A38: Other assets | B38: 247937251
A60: Growth Comparison
A61: Total Assets | B61: =(B9-C9)/C9 -> 0.36656081
A62: Net Advances | B62: =(B10-C10)/C10 -> 0.6552915
A63: Total Deposits | B63: =(B11-C11)/C11 -> 0.0019584209
A64: Profit After Taxation | B64: =(B12-C12)/C12 -> 0.34188433
...

Sheet Statement of Financial Position
A1: Statement of financial position(UBL) | B1: Note | C1: 2024 | D1: 2023
C2: (Rupees in '000) | D2: (Rupees in '000)
A3: ASSETS
A4: Cash and balances with treasury banks | B4: 5 | C4: 310836376 | D4: 277355760
A5: Balances with other banks | B5: 6 | C5: 59968246 | D5: 33430371
A6: Lendings to financial institutions | B6: 7 | C6: 18492483 | D6: 39316270
A7: Investments | B7: 8 | C7: 5889765841 | D7: 4435750870
A8: Advances | B8: 9 | C8: 1443481944 | D8: 872040932
A9: Property and Equipment | B9: 10 | C9: 85591999 | D9: 76460159
A10: Right-of-use of assets | B10: 11 | C10: 10231121 | D10: 8611473
A11: Intangible assets | B11: 12 | C11: 2792016 | D11: 2552398
A12: Deferred tax assets | B12: 13
A13: Other assets | B13: 14 | C13: 247937251 | D13: 159156653
C14: =SUM(C4:C13) -> 8069097277 | D14: =SUM(D4:D13) -> 5904674886
A15: LIABILITIES
A16: Bills payable | B16: 16 | C16: 44221818 | D16: 21734531
A17: Borrowings | B17: 17 | C17: 4855373516 | D17: 2823887914
A18: Deposits and other accounts | B18: 18 | C18: 2639875985 | D18: 2634716102
A19: Lease liabilities | B19: 19 | C19: 12381018 | D19: 10474561
A20: Subordinated debt | B20: 20 | C20: 10000000 | D20: 10000000
A21: Deferred tax liabilities | B21: 13 | C21: 39311263 | D21: 2079220
A22: Other liabilities | B22: 21 | C22: 147125664 | D22: 115909963
C23: =SUM(C16:C22) -> 7748289264 | D23: =SUM(D16:D22) -> 5618802291
A24: NET ASSETS | C24: =C14-C23 -> 320808013 | D24: =D14-D23 -> 285872595
A26: REPRESENTED BY:
A27: Share capital | B27: 22 | C27: 12241797 | D27: 12241797
A28: Reserves | C28: 114734831 | D28: 116771416
A29: Surplus on revaluation of assets - net | B29: 23 | C29: 77309424 | D29: 44575947
A30: Unappropriated profit | C30: 116472051 | D30: 97379056
A31: Total equity attributable to the equity holders of the Bank | C31: =SUM(C27:C30) -> 320758103 | D31: =SUM(D27:D30) -> 270968216
A32: Non-controlling interest | B32: 24 | C32: 49910 | D32: 14904379
C33: =C31+C32 -> 320808013 | D33: =D31+D32 -> 285872595

Sheet Profit and Loss Statement
A1: Profit and loss statemnet (UBL) | B1: Note | C1: 2024 | D1: 2023
C2: (Rupees in '000) | D2: (Rupees in '000)
A3: Mark-up / return/interest earned | B3: 27 | C3: 1084641497 | D3: 535211524
A4: Mark-up/return/interest expensed | B4: 28 | C4: 911093616 | D4: 386236455
A5: Net mark-up / interest income | C5: =C3-C4 -> 173547881 | D5: =D3-D4 -> 148975069
A7: Non mark-up / interest income
A8: Fee and commission income | B8: 29 | C8: 21535329 | D8: 19751084
A9: Dividend income | C9: 1741707 | D9: 1614470
A10: Foreign exchange income | C10: 12559992 | D10: 12715845
A11: Gain / (Loss) on derivatives | C11: 1230801 | D11: -65266
A12: Gain on securities - net | B12: 30 | C12: 42592701 | D12: 532782
A13: Capital gain on derecognition of financial assets measured at amortised cost | C13: 2894427 | D13: 0
A14: Other income | B14: 31 | C14: 1139575 | D14: 1523109
A15: Total non mark-up/interest income | C15: =SUM(C8:C14) -> 83694532 | D15: =SUM(D8:D14) -> 36072024
A16: Total income | C16: =C5+C15 -> 257242413 | D16: =D5+D15 -> 185047093
A18: Non mark-up / interest expenses
A19: Operating expenses | B19: 32 | C19: 97104258 | D19: 70093696
A20: Workers' Welfare Fund | C20: 3145755 | D20: 2158813
A21: Other charges | B21: 34 | C21: 75270 | D21: 240326
A22: Total non mark-up/interest expenses | C22: =SUM(C19:C21) -> 100325283 | D22: =SUM(D19:D21) -> 72492835
A24: Share of gain / (loss) of associates | C24: 895183 | D24: -989536
A25: Profit before credit loss allowance | C25: =C16-C22+C24 -> 157812313 | D25: =D16-D22+D24 -> 111564722
A26: Credit loss allowance / provisions and write-offs - net | B26: 35 | C26: 12775474 | D26: 980157
A27: Profit before taxation from continuing operations | C27: =C25-C26 -> 145036839 | D27: =D25-D26 -> 110584565
A29: Taxation | B29: 36 | C29: 70198005 | D29: 54113644
A31: Profit after taxation from continuing operations | C31: =C27-C29 -> 74838834 | D31: =D27-D29 -> 56470921
A33: Discontinued operations
A34: Profit from discontinued operations - net of tax | C34: 938610 | D34: 0
C35: =C31+C34 -> 75777444 | D35: =D31+D34 -> 56470921
A37: Attributable to:
A38: Equity holders of the Bank
A39: from continuing operations | C39: 74823735 | D39: 55145075
A40: from discontinued operations | C40: 332118 | D40: 0
C41: =C39+C40 -> 75155853 | D41: =D39+D40 -> 55145075
A42: Non-controlling interest | C42: 15099 | D42: 1325846
A43: from continuing operations | C43: 606492
A44: from discontinued operation | C44: =C42+C43 -> 621591 | D44: =D42+D43 -> 1325846
C45: =C41+C44 -> 75777444 | D45: =D41+D44 -> 56470921
C46: (Rupees) | D46: (Rupees)
A47: Earnings per share for profit from continuing operations attributable to the equity holders of the Bank
...

Sheet  Comprehensive Income
A1: Statement of comprehensive income | B1: 2024 | C1: 2023
B2: (Rupees in '000) | C2: (Rupees in '000)
A3: Profit after taxation for the year attributable to:
A4: Equity holders of the Bank | B4: 75155853 | C4: 55145075
A5: Non-controlling interest | B5: 621591 | C5: 1325846
B6: =B4+B5 -> 75777444 | C6: =C4+C5 -> 56470921
A7: Other comprehensive income
A9: Items that may be reclassified to profit and loss account in subsequent periods
A11: Effect of translation of net investment in foreign branches and subsidiaries
A13: Equity holders of the Bank | B13: -1382628 | C13: 19564664
A14: Non-controlling interest | B14: -217940 | C14: 2739248
B15: =B13+B14 -> -1600568 | C15: =C13+C14 -> 22303912
A16: Less: Reserve reclassified to profit and loss on disposal of subsidiary | B16: -8706711 | C16: 0
B17: =B15+B16 -> -10307279 | C17: =C15-C16 -> 22303912
A18: Movement in surplus / (deficit) on revaluation of debt investments through FVOCI - net of tax
A19: Equity holders of the Bank | B19: 33607524 | C19: 23880646
A20: Non-controlling interest | B20: 405717 | C20: 922755
B21: =B19+B20 -> 34013241 | C21: =C19+C20 -> 24803401
B22: =B17+B21 -> 23705962 | C22: =C17+C21 -> 47107313
A23: Items that will not be reclassified to profit and loss account in subsequent periods
A25: Re measurement gain on defined benefit obligations - net of tax
A26: Equity holders of the Bank | B26: 4197565 | C26: 1122792
A27: Non-controlling interest | B27: 370 | C27: 49480
B28: =B26+B27 -> 4197935 | C28: =C26+C27 -> 1172272
A29: Movement in surplus on revaluation of investment in equity investments - net of tax
A30: Equity holders of the Bank | B30: 4856315 | C30: 1688431
A31: Non-controlling interest | B31: 0 | C31: 0
B32: =B30+B31 -> 4856315 | C32: =C30+C31 -> 1688431
A33: Movement in surplus on revaluation of property and equipment - net of tax
A34: Equity holders of the Bank | B34: 252545 | C34: 915183
A35: Non-controlling interest | B35: -74091 | C35: 741749
B36: =B34+B35 -> 178454 | C36: =C34+C35 -> 1656932
A37: Movement in surplus on revaluation of non-banking assets - net of tax
A38: Equity holders of the Bank | B38: 1146 | C38: 0
B39: =SUM(B28,B32,B36,B38) -> 9233850 | C39: =SUM(C28,C32,C36,C38) -> 4517635
A40: Total comprehensive income for the year | B40: =SUM(B6+B22+B39) -> 108717256 | C40: =SUM(C6+C22+C39) -> 108095869
A42: Attributable to:
A43: Equity holders of the Bank | B43: 107981609 | C43: 102316791
A44: Non-controlling interest | B44: 735647 | C44: 5779078
B45: =SUM(B43:B44) -> 108717256 | C45: =SUM(C43:C44) -> 108095869

Sheet Statement of Changes in Equity
A1: Changes in equity | B1: Column1 | C1: Column3 | D1: Column4 | E1: Column5 | F1: Column6 | G1: Column7 | H1: Column8 | I1: Column9 | J1: Column10 | K1: Column11 | L1: Column12 | M1: Column13
D2: Attributable to equity holders of the Bank
B3: Share capital | C3: Statutory reserve | D3: Capital reserve exchange translation | F3: Surplus/(deficit) on revaluation of :- | H3: Unappropriated profit | I3: Subtotal | J3: Non controlling interest | K3: Total
E4: Investments | F4: Property and Equipment | G4: Non Banking Assests
B5: ( Rupees in '000 ) | C5: ( Rupees in '000 ) | D5: ( Rupees in '000 ) | E5: ( Rupees in '000 ) | F5: ( Rupees in '000) | G5: ( Rupees in '000 ) | H5: ( Rupees in '000) | I5: ( Rupees in '000 ) | J5: ( Rupees in '000) | K5: ( Rupees in '000 )
A6: Balance as at January 01,2023 | B6: 12241797 | C6: 41560081 | D6: 50328629 | E6: -22788440 | F6: 42442737 | G6: 0 | H6: 96282169 | I6: 220006973 | J6: 9125301 | K6: =I6+J6 -> 229132274
A7: Total comprehensive income for the year ended December 31, 2023
A8: Profit after taxation for the year ended December 31, 2023 | B8: 0 | C8: 0 | D8: 0 | G8: 0 | H8: 55145075 | I8: =SUM(B8:H8) -> 55145075 | J8: 1325846 | K8: =I8+J8 -> 56470921
A9: Other comprehensive income - net of tax | B9: 0 | C9: 0 | D9: 19564664 | E9: 25569077 | F9: 915183 | G9: 0 | H9: 1122792 | I9: =SUM(B9:H9) -> 47171716 | J9: 4453232 | K9: =I9+J9 -> 51624948
A10: Total comprehensive income for the year ended December 31, 2023 | B10: =SUM(B8:B9) -> 0 | C10: =SUM(C8:C9) -> 0 | D10: =SUM(D8:D9) -> 19564664 | E10: =SUM(E8:E9) -> 25569077 | F10: =SUM(F8:F9) -> 915183 | G10: =SUM(G8:G9) -> 0 | H10: =SUM(H8:H9) -> 56267867 | I10: =SUM(I8:I9) -> 102316791 | J10: =SUM(J8:J9) -> 5779078 | K10: =I10+J10 -> 108095869
A11: Transfer from surplus on revaluation upon disposal to unappropriated profit - net of tax | B11: 0 | C11: 0 | D11: 0 | E11: 0 | F11: -1474233 | G11: 0 | H11: 1474233 | I11: 0 | J11: 0 | K11: =I11+J11 -> 0
A12: Transfer of incremental depreciation from revaluation of property and equipment to unappropriated profit - net of tax | B12: 0 | C12: 0 | D12: 0 | E12: 0 | F12: -88377 | G12: 0 | H12: 88377 | I12: 0 | J12: 0 | K12: =I12+J12 -> 0
A13: Transfer to statutory reserve | B13: 0 | C13: 5318042 | D13: 0 | E13: 0 | F13: 0 | G13: 0 | H13: -5318042 | I13: 0 | J13: 0 | K13: =I13+J13 -> 0
A14: Transfer from statutory reserve on liquidation of subsidiary | B14: 0 | C14: 0 | D14: 0 | E14: 0 | F14: 0 | G14: 0 | H14: 0 | I14: 0 | J14: 0 | K14: =I14+J14 -> 0
A15: Transactions with owners, recorded directly in equity | G15: 0
A16: Final cash dividend - December 31, 2022 declared subsequent to the year end at Rs. 9.0 per share | B16: 0 | C16: 0 | D16: 0 | E16: 0 | F16: 0 | G16: 0 | H16: -11017617 | I16: -11017617 | J16: 0 | K16: =I16+J16 -> -11017617
A17: Interim cash dividend - March 31, 2023 declared at Rs. 11.0 per share | B17: 0 | C17: 0 | D17: 0 | E17: 0 | F17: 0 | G17: 0 | H17: -13465977 | I17: -13465977 | J17: 0 | K17: =I17+J17 -> -13465977
A18: Interim cash dividend - June 30, 2023 declared at Rs. 11.0 per share | B18: 0 | C18: 0 | D18: 0 | E18: 0 | F18: 0 | G18: 0 | H18: -13465977 | I18: -13465977 | J18: 0 | K18: =I18+J18 -> -13465977
A19: Interim cash dividend - September 30, 2023 declared at Rs. 11.0 per share | B19: 0 | C19: 0 | D19: 0 | E19: 0 | F19: 0 | G19: 0 | H19: -13465977 | I19: -13465977 | J19: 0 | K19: =I19+J19 -> -13465977
B20: =SUM(B16:B19) -> 0 | C20: =SUM(C16:C19) -> 0 | D20: =SUM(D16:D19) -> 0 | E20: =SUM(E16:E19) -> 0 | F20: =SUM(F16:F19) -> 0 | G20: =SUM(G16:G19) -> 0 | H20: =SUM(H16:H19) -> -51415548 | I20: =SUM(I16:I19) -> -51415548 | J20: =SUM(J16:J19) -> 0 | K20: =I20+J20 -> -51415548
A21: Balance as at December 31, 2023 | B21: =SUM(B6,B10:B14,B20) -> 12241797 | C21: =SUM(C6,C10:C14,C20) -> 46878123 | D21: =SUM(D6,D10:D14,D20) -> 69893293 | E21: =SUM(E6,E10:E14,E20) -> 2780637 | F21: =SUM(F6,F10:F14,F20) -> 41795310 | G21: =SUM(G6,G10:G14,G20) -> 0 | H21: =SUM(H6,H10:H14,H20) -> 97379056 | I21: =SUM(B21:H21) -> 270968216 | J21: 14904379 | K21: =I21+J21 -> 285872595
A22: Effect of reclassification on adoption of IFRS 9-ECL (net of tax) | B22: 0 | C22: 0 | D22: 0 | E22: -2973630 | F22: 0 | G22: 0 | H22: 2973630 | I22: =SUM(B22:H22) -> 0 | J22: 0 | K22: =I22+J22 -> 0
A23: Effect of adoption of IFRS 9 - ECL (net of tax) | B23: 0 | C23: 0 | D23: 0 | E23: 0 | F23: 0 | G23: 0 | H23: -4327814 | I23: -4327814 | J23: 0 | K23: =I23+J23 -> -4327814
B24: =SUM(B22:B23) -> 0 | C24: =SUM(C22:C23) -> 0 | D24: =SUM(D22:D23) -> 0 | E24: =SUM(E22:E23) -> -2973630 | F24: =SUM(F22:F23) -> 0 | G24: =SUM(G22:G23) -> 0 | H24: =SUM(H22:H23) -> -1354184 | I24: =SUM(B24:H24) -> -4327814 | J24: 0 | K24: =I24+J24 -> -4327814
A25: Balance as at January 01, 2024 - Restated | B25: =B21+B24 -> 12241797 | C25: 46878123 | D25: 69893293 | E25: -192993 | F25: 41795310 | G25: 0 | H25: 96024872 | I25: 266640402 | J25: 14904379 | K25: =I25+J25 -> 281544781
A26: Total comprehensive income for the year ended December 31, 2024 | G26: 0
A27: Profit after taxation for the year ended December 31, 2024 | B27: 0 | C27: 0 | D27: 0 | E27: 0 | F27: 0 | G27: 0 | H27: 75155853 | I27: =SUM(B27:H27) -> 75155853 | J27: 621591 | K27: =I27+J27 -> 75777444
A28: Other comprehensive income - net of tax | B28: 0 | C28: 0 | D28: -10089339 | E28: 38463839 | F28: 252545 | G28: 1146 | H28: 4197565 | I28: =SUM(B28:H28) -> 32825756 | J28: 114056 | K28: =I28+J28 -> 32939812
A29: Total comprehensive income for the year ended December 31, 2024 | B29: =B27+B28 -> 0 | C29: =C27+C28 -> 0 | D29: =D27+D28 -> -10089339 | E29: =E27+E28 -> 38463839 | F29: =F27+F28 -> 252545 | G29: =G27+G28 -> 1146 | H29: =H27+H28 -> 79353418 | I29: =SUM(B29:H29) -> 107981609 | J29: 735647 | K29: =I29+J29 -> 108717256
A30: Transfer from surplus on revaluation upon disposal to unappropriated profit - net of tax | B30: 0 | C30: 0 | D30: 0 | E30: 0 | F30: -22930 | G30: 0 | H30: 22930 | I30: =SUM(B30:H30) -> 0 | J30: 0 | K30: =I30+J30 -> 0
A31: Transfer of incremental depreciation from revaluation of property and equipment to unappropriated profit - net of tax | B31: 0 | C31: 0 | D31: 0 | E31: 0 | F31: -78513 | G31: 0 | H31: 78513 | I31: =SUM(B31:H31) -> 0 | J31: 0 | K31: =I31+J31 -> 0
A32: Transfer to statutory reserve | B32: 0 | C32: 8052754 | D32: 0 | E32: 0 | F32: 0 | G32: 0 | H32: -8052754 | I32: =SUM(B32:H32) -> 0 | J32: 0 | K32: =I32+J32 -> 0
A33: Transfer of net loss on disposal of FVOCI equity investments from surplus to unappropriated profit - net of tax | B33: 0 | C33: 0 | D33: 0 | E33: 48249 | F33: 0 | G33: 0 | H33: -48249 | I33: =SUM(B33:H33) -> 0 | J33: 0 | K33: =I33+J33 -> 0
A34: Nonrecognition of subsidiary | B34: 0 | C34: 0 | D34: 0 | E34: 535734 | F34: -3492963 | G34: 0 | H34: 2957229 | I34: =SUM(B34:H34) -> 0 | J34: -15590116 | K34: =I34+J34 -> -15590116
A35: Transactions with owners, recorded directly in equity
A36: Final cash dividend - December 31, 2023 declared subsequent to the year end at Rs. 11.0 per share | B36: 0 | C36: 0 | D36: 0 | E36: 0 | F36: 0 | G36: 0 | H36: -13465977 | I36: -13456977 | J36: 0 | K36: =I36+J36 -> -13456977
A37: Interim cash dividend - March 31, 2024 declared at Rs. 11.0 per share | B37: 0 | C37: 0 | D37: 0 | E37: 0 | F37: 0 | G37: 0 | H37: -13465977 | I37: -13456977 | J37: 0 | K37: =I37+J37 -> -13456977
A38: Interim cash dividend - June 30, 2024 declared at Rs. 11.0 per share | B38: 0 | C38: 0 | D38: 0 | E38: 0 | F38: 0 | G38: 0 | H38: -13465977 | I38: -13456977 | J38: 0 | K38: =I38+J38 -> -13456977
A39: Interim cash dividend - September 30, 2024 declared at Rs. 11.0 per share | B39: 0 | C39: 0 | D39: 0 | E39: 0 | F39: 0 | G39: 0 | H39: -13465977 | I39: -13456977 | J39: 0 | K39: =I39+J39 -> -13456977
B40: =SUM(B36:B39) -> 0 | C40: =SUM(C36:C39) -> 0 | D40: =SUM(D36:D39) -> 0 | E40: =SUM(E36:E39) -> 0 | F40: =SUM(F36:F39) -> 0 | G40: =SUM(G36:G39) -> 0 | H40: =SUM(H36:H39) -> -53863908 | I40: =SUM(I36:I39) -> -53827908 | J40: =SUM(J36:J39) -> 0 | K40: =I40+J40 -> -53827908
...

Sheet Cash Flow Statement
A1: CASH FLOW STATMENT | B1: Note | C1: 2024 | D1: 2023
C2: (Rupees in '000) | D2: (Rupees in '000)
A3: CASH FLOW FROM OPERATING ACTIVITIES
A4: Profit before taxation including discontinued operations | C4: 145036839 | D4: 110584565
A5: Less: Dividend income | C5: -1741707 | D5: -1614470
A6: (Less) / Add: Share of gain / loss of associates | C6: -895183 | D6: 989536
C7: =SUM(C4:C6) -> 142399949 | D7: =SUM(D4:D6) -> 109959631
A8: Adjustments:
A9: Depreciation on property and equipment | C9: 5849218 | D9: 4524584
A10: Depreciation on right-of-use assets | C10: 2520644 | D10: 2336379
A11: Depreciation on non-banking assets acquired in satisfaction of claims | C11: 3226 | D11: 3012
A12: Depreciation on Islamic financing against leased assets (ljarah) | C12: 79527 | D12: 135236
A13: Amortisation | C13: 1022553 | D13: 1085264
A14: Workers Welfare Fund | C14: 3145755 | D14: 2158813
A15: Provision for retirement benefits | C15: 91706 | D15: 650477
A16: Credit loss allowance against loans and advances - net | C16: 11253648 | D16: -4893500
A17: Credit loss allowance against off-balance sheet obligations - net | C17: 1303408 | D17: -29304
A18: Credit loss allowance for diminution in value of investments - net | C18: -15723998 | D18: 6110045
A19: Interest expense on lease liability against right-of-use assets | C19: 1504645 | D19: 1236242
A20: Gain on sale of operating property and equipment - net | C20: -234287 | D20: -487633
A21: Transfer of exchange translation reserve to profit and loss on nonrecognition of subsidiary | C21: -8706711
A22: Gain on sale of Ijarah assets - net | C22: -1016 | D22: -2068
A23: Bad debts written off directly | C23: 54951 | D23: 149845
A24: Unrealized gain on revaluation of investments classified as FVPL | C24: -35068 | D24: 79074
A25: Credit loss allowance against other assets | C25: 476252 | D25: -29016
A26: Other provisions / write-offs | C26: 160014 | D26: 149432
C27: =SUM(C9:C26) -> 2764467 | D27: =SUM(D9:D26) -> 13176882
C28: =C7+C27 -> 145164416 | D28: =D7+D27 -> 123136513
A29: (Increase) / decrease in operating assets
A30: Lendings to financial institutions | C30: 20823787 | D30: 46526451
A31: Securities cassified as FVPL | C31: 55025621 | D31: -51489494
A32: Advances | C32: -582847466 | D32: 228743108
A33: Other assets (excluding advance taxation) | C33: -79237101 | D33: -72368543
C34: =SUM(C30:C33) -> -586235159 | D34: =SUM(D30:D33) -> 151411522
A35: Increase / (decrease) in operating liabilities
A36: Bills payable | C36: 22487287 | D36: -11295902
A37: Borrowings | C37: 2031485602 | D37: 2257653694
A38: Deposits and other accounts | C38: 5159883 | D38: 596706389
A39: Other liabilities | C39: 27144404 | D39: 18975940
C40: =SUM(C36:C39) -> 2086277176 | D40: =SUM(D36:D39) -> 2862040121
...

Sheet Working Capital Statement
A1: Working capital Statment | B1: Note | C1: 2024 | D1: 2023
C2: (Rupees in '000) | D2: (Rupees in '000)
A3: Current Assets
A4: Cash and balances with treasury banks | B4: 5 | C4: 310836376 | D4: 277355760
A5: Balances with other banks | B5: 6 | C5: 59968246 | D5: 33430371
A6: Lendings to financial institutions | B6: 7 | C6: 18492483 | D6: 39316270
A7: Investments | B7: 8 | C7: 5889765841 | D7: 4435750870
A8: Advances | B8: 9 | C8: 1443481944 | D8: 872040932
A9: Other assets | B9: 14 | C9: 247937251 | D9: 159156653
C10: =SUM(C4:C9) -> 7970482141 | D10: =SUM(D4:D9) -> 5817050856
A11: Current Liabilities
A12: Bills payable | B12: 16 | C12: 44221818 | D12: 21734531
A13: Borrowings | B13: 17 | C13: 4855373516 | D13: 2823887914
A14: Deposits and other accounts | B14: 18 | C14: 2639875985 | D14: 2634716102
A15: Lease liabilities | B15: 19 | C15: 12381018 | D15: 10474561
A16: Subordinated debt | B16: 20 | C16: 10000000 | D16: 10000000
A17: Deferred tax liabilities | B17: 13 | C17: 39311263 | D17: 2079220
A18: Other liabilities | B18: 21 | C18: 147125664 | D18: 115909963
C19: =SUM(C12:C18) -> 7748289264 | D19: =SUM(D12:D18) -> 5618802291
A20: Working capital | C20: =C10-C19 -> 222192877 | D20: =D10-D19 -> 198248565

Sheet Notes to  Financial Statement
A1: Notes to Financial Statment
A2: Note 5
B3: 2024 | C3: 2023
B4: (Rupees in '000)
A5: CASH AND BALANCES WITH TREASURY BANKS
A6: In hand
A7: Local currency | B7: 53476586 | C7: 27876981
A8: Foreign currencies | B8: 8928893 | C8: 13068432
B9: =SUM(B7:B8) -> 62405479 | C9: =SUM(C7:C8) -> 40945413
A10: With State Bank of Pakistan in
A11: Local currency current accounts | B11: 108175484 | C11: 88035634
A12: Foreign currency current accounts | B12: 5094782 | C12: 5306080
A13: Foreign currency deposit account | B13: 8205041 | C13: 9473621
B14: =SUM(B11:B13) -> 121475307 | C14: =SUM(C11:C13) -> 102815335
A15: With other central banks in
A16: Foreign currency current accounts | B16: 88215425 | C16: 50093433
A17: Foreign currency deposit accounts | B17: 19326856 | C17: 10684831
B18: =SUM(B16:B17) -> 107542281 | C18: =SUM(C16:C17) -> 60778264
A19: With National Bank of Pakistan in
A20: Local currency current accounts | B20: 19133450 | C20: 72368067
A22: National Prize Bonds | B22: 479356 | C22: 448681
B23: =B9+B14+B18+B20+B22 -> 311035873 | C23: =C9+C14+C18+C20+C22 -> 277355760
A24: Less Credit loss allowance held against cash and balances with treasury banks | B24: -199497 | C24: 0
A26: Cash and balances with treasury banks - net of credit loss allowance | B26: =B23+B24 -> 310836376 | C26: =C23+C24 -> 277355760
A28: Note 6
A29: BALNACES WITH OTHER BANKS | B29: 2024 | C29: 2023
B30: (Rupees in '000)
A31: In Pakistan
A32: In current account | B32: 0 | C32: 1659
A33: In deposit account | B33: 7 | C33: 7
B34: =SUM(B32:B33) -> 7 | C34: =SUM(C32:C33) -> 1666
A35: Outside Pakistan
A36: In current account | B36: 47801939 | C36: 26393747
A37: In deposit account | B37: 12173491 | C37: 7034958
B38: =SUM(B36:B37) -> 59975430 | C38: =SUM(C36:C37) -> 33428705
B39: =B34+B38 -> 59975437 | C39: =C34+C38 -> 33430371
A40: Less: Credit loss allowance held against balances with other banks | B40: -7191 | C40: 0
A42: Balances with Other Banks - net of credit loss allowance | B42: =B39+B40 -> 59968246 | C42: =C39+C40 -> 33430371
A44: Note 7
A45: LENDINGS TO FINANCIAL INSTITUTIONS | B45: 2024 | C45: 2023
...
